<?xml version="1.0"?>
<robot xmlns:xacro="http://www.ros.org/wiki/xacro" name="robot_xacro">
<xacro:include filename="$(find assignment2)/urdf/robot.gazebo"/>

<!-- Properties -->
<xacro:property name="wheel_thickness" value="0.04"/>
<xacro:property name="wheel_radius" value="0.08"/>

<!-- Macros -->
<xacro:macro name="default_inertial" params="mass">
  <inertial>
    <mass value="${mass}"/>
    <origin rpy="0 1.5707 1.5707" xyz="0 0 0"/>
    <inertia ixx="0.0005267" ixy="0" ixz="0" iyy="0.0005267" iyz="0" izz="0.001"/>
  </inertial>
</xacro:macro>

<xacro:macro name="wheel_geometry">
  <geometry>
    <cylinder length="${wheel_thickness}" radius="${wheel_radius}"/>
  </geometry>
</xacro:macro>

<!-- Materials -->
<material name="black">
  <color rgba="0.0 0.0 0.0 1.0"/>
</material>
<material name="blue">
  <color rgba="0.203125 0.23828125 0.28515625 1.0"/>
</material>
<material name="green">
  <color rgba="0.0 0.8 0.0 1.0"/>
</material>
<material name="grey">
  <color rgba="0.2 0.2 0.2 1.0"/>
</material>
<material name="orange">
  <color rgba="1.0 0.423529411765 0.0392156862745 1.0"/>
</material>
<material name="brown">
  <color rgba="0.870588235294 0.811764705882 0.764705882353 1.0"/>
</material>
<material name="red">
  <color rgba="0.80078125 0.12890625 0.1328125 1.0"/>
</material>
<material name="white">
  <color rgba="1.0 1.0 1.0 1.0"/>
</material>

<!-- Robot -->
<link name="link_chassis">
  <!-- Pose and Inertial Matrix -->
  <pose>0 0 0 0 0 0</pose>
  <inertial>
    <mass value="5"/>
    <origin rpy="0 0 0" xyz="0 0 0"/>
    <inertia ixx="0.0395416666667" ixy="0" ixz="0" iyy="0.106208333333" iyz="0" izz="0.106208333333"/>
  </inertial>

  <!-- Body -->
  <collision name="collision_chassis">
    <geometry>
      <box size="0.5 0.3 0.07"/>
    </geometry>
  </collision>
  <visual>
    <origin rpy="0 0 0" xyz="0 0 0"/>
    <geometry>
      <box size="0.5 0.3 0.07"/>
    </geometry>
    <material name="blue"/>
  </visual>
</link>

<!-- Wheel Links -->
<link name="link_right_front_wheel">
  <xacro:default_inertial mass="0.5"/>
  <collision name="link_right_wheel_collision">
    <origin rpy="0 1.5707 1.5707" xyz="0 0 0"/>
    <xacro:wheel_geometry />
  </collision>
  <visual name="link_right_wheel_visual">
    <origin rpy="0 1.5707 1.5707" xyz="0 0 0"/>
    <xacro:wheel_geometry />
    <material name="red"/>
  </visual>
</link>

<link name="link_left_front_wheel">
  <xacro:default_inertial mass="0.5"/>
  <collision name="link_left_wheel_collision">
    <origin rpy="0 1.5707 1.5707" xyz="0 0 0"/>
    <xacro:wheel_geometry />
  </collision>
  <visual name="link_left_wheel_visual">
    <origin rpy="0 1.5707 1.5707" xyz="0 0 0"/>
    <xacro:wheel_geometry />
    <material name="red"/>
  </visual>
</link>

<link name="link_right_rear_wheel">
  <xacro:default_inertial mass="0.5"/>
  <collision name="link_right_wheel_collision">
    <origin rpy="0 1.5707 1.5707" xyz="0 0 0"/>
    <xacro:wheel_geometry />
  </collision>
  <visual name="link_right_wheel_visual">
    <origin rpy="0 1.5707 1.5707" xyz="0 0 0"/>
    <xacro:wheel_geometry />
    <material name="red"/>
  </visual>
</link>

<link name="link_left_rear_wheel">
  <xacro:default_inertial mass="0.5"/>
  <collision name="link_left_wheel_collision">
    <origin rpy="0 1.5707 1.5707" xyz="0 0 0"/>
    <xacro:wheel_geometry />
  </collision>
  <visual name="link_left_wheel_visual">
    <origin rpy="0 1.5707 1.5707" xyz="0 0 0"/>
    <xacro:wheel_geometry />
    <material name="red"/>
  </visual>
</link>

<joint name="joint_right_front_wheel" type="continuous">
  <origin rpy="0 0 0" xyz="0.12 -0.15 0"/>
  <child link="link_right_front_wheel"/>
  <parent link="link_chassis"/>
  <axis rpy="0 0 0" xyz="0 1 0"/>
  <limit effort="2000" velocity="200"/>
  <joint_properties damping="1.0" friction="1.0"/>
</joint>

<joint name="joint_left_front_wheel" type="continuous">
  <origin rpy="0 0 0" xyz="0.12 0.15 0"/>
  <child link="link_left_front_wheel"/>
  <parent link="link_chassis"/>
  <axis rpy="0 0 0" xyz="0 1 0"/>
  <limit effort="2000" velocity="200"/>
  <joint_properties damping="1.0" friction="1.0"/>
</joint>

<joint name="joint_right_rear_wheel" type="continuous">
  <origin rpy="0 0 0" xyz="-0.12 -0.15 0"/>
  <child link="link_right_rear_wheel"/>
  <parent link="link_chassis"/>
  <axis rpy="0 0 0" xyz="0 1 0"/>
  <limit effort="2000" velocity="200"/>
  <joint_properties damping="1.0" friction="1.0"/>
</joint>

<joint name="joint_left_rear_wheel" type="continuous">
  <origin rpy="0 0 0" xyz="-0.12 0.15 0"/>
  <child link="link_left_rear_wheel"/>
  <parent link="link_chassis"/>
  <axis rpy="0 0 0" xyz="0 1 0"/>
  <limit effort="2000" velocity="200"/>
  <joint_properties damping="1.0" friction="1.0"/>
</joint>

<!-- Sensors -->

<!-- Hokuyo -->
<link name="link_hokuyo">
  <collision>
    <origin xyz="0 0 0" rpy="0 0 0"/>
    <geometry>
      <box size="0.1 0.1 0.1"/>
    </geometry>
  </collision>
  <visual>
    <origin xyz="0 0 0" rpy="0 0 0"/>
    <geometry>
      <mesh filename="package://assignment2/meshes/hokuyo.dae"/>
    </geometry>
    <material name="red">
      <color rgba="1 0 0 1"/>
    </material>
  </visual>
  <inertial>
    <mass value="1e-5" />
    <origin xyz="0 0 0" rpy="0 0 0"/>
    <inertia ixx="1e-6" ixy="0" ixz="0" iyy="1e-6" iyz="0" izz="1e-6" />
  </inertial>
</link>

<joint name="joint_hokuyo" type="fixed">
  <axis rpy="0 0 0" xyz="0 0 1" />
  <origin rpy="0 0 0" xyz="0 0 0.1"/>
  <parent link="link_chassis"/>
  <child link="link_hokuyo"/>
</joint>

<!-- RGB Camera -->
<link name="link_camera">
  <collision>
    <origin xyz="0 0 0" rpy="0 0 0"/>
    <geometry>
      <box size="0.02 0.02 0.02"/>
    </geometry>
  </collision>

  <visual>
    <origin xyz="0 0 0" rpy="0 0 0"/>
    <geometry>
      <box size="0.02 0.02 0.02"/>
    </geometry>
    <material name="blue"/>
  </visual>

  <inertial>
    <mass value="0.001" />
    <origin xyz="0 0 0" rpy="0 0 0"/>
    <inertia ixx="0.0" ixy="0" ixz="0" iyy="0.0" iyz="0" izz="0.0" />
  </inertial>
</link>

<link name="link_camera_vertical">
  <collision>
    <origin xyz="0 0 0" rpy="0 0 0"/>
    <geometry>
      <box size="0.01 0.01 0.0"/>
    </geometry>
  </collision>

  <visual>
    <origin xyz="0 0 0" rpy="0 0 0"/>
    <geometry>
      <box size="0.01 0.01 0.0"/>
    </geometry>
    <material name="blue"/>
  </visual>

  <inertial>
    <mass value="0.1" />
    <origin xyz="0 0 0" rpy="0 0 0"/>
    <inertia ixx="0" ixy="0" ixz="0" iyy="0" iyz="0" izz="0" />
  </inertial>
</link>

<joint name="joint_camera" type="continuous">
  <axis rpy="0 0 0" xyz="0 0 1" />
  <origin rpy="0 0 0" xyz="0 0 0"/>
  <parent link="link_camera_vertical"/>
  <child link="link_camera"/>
  <limit effort="1000" velocity="10"/>
  <joint_properties damping="1.0" friction="1.0"/>
</joint>

<joint name="joint_camera_vertical" type="prismatic">
  <axis rpy="0 0 0" xyz="0 0 1" />
  <origin rpy="0 0 0" xyz="0 0 0.15"/>
  <parent link="link_chassis"/>
  <child link="link_camera_vertical"/>
  <limit effort="1000" velocity="0.5" lower="0.0" upper="2.0"/>
  <joint_properties damping="1.0" friction="1.0"/>
</joint>

<!-- Trasmission for camera rotation joint -->
<transmission name="trans_joint_camera">
  <type>transmission_interface/SimpleTransmission</type>
  <actuator name="motor_joint_camera">
    <hardwareInterface>hardware_interface/EffortJointInterface</hardwareInterface>
    <mechanicalReduction>1</mechanicalReduction>
  </actuator>
  <joint name="joint_camera">
    <hardwareInterface>hardware_interface/EffortJointInterface</hardwareInterface>
  </joint>
</transmission>

<!-- Trasmission for camera prismatic joint -->
<transmission name="trans_joint_camera_vertical">
  <type>transmission_interface/SimpleTransmission</type>
  <actuator name="motor_joint_camera_vertical">
    <hardwareInterface>hardware_interface/EffortJointInterface</hardwareInterface>
    <mechanicalReduction>1</mechanicalReduction>
  </actuator>
  <joint name="joint_camera_vertical">
    <hardwareInterface>hardware_interface/EffortJointInterface</hardwareInterface>
  </joint>
</transmission>

</robot>
